[2023-03-22T07:27:02.937+0000] {taskinstance.py:1084} INFO - Dependencies all met for dep_context=non-requeueable deps ti=<TaskInstance: sql_dags.load_from_mysql manual__2023-03-22T07:21:59.284653+00:00 [queued]>
[2023-03-22T07:27:02.946+0000] {taskinstance.py:1084} INFO - Dependencies all met for dep_context=requeueable deps ti=<TaskInstance: sql_dags.load_from_mysql manual__2023-03-22T07:21:59.284653+00:00 [queued]>
[2023-03-22T07:27:02.947+0000] {taskinstance.py:1282} INFO - 
--------------------------------------------------------------------------------
[2023-03-22T07:27:02.947+0000] {taskinstance.py:1283} INFO - Starting attempt 2 of 2
[2023-03-22T07:27:02.948+0000] {taskinstance.py:1284} INFO - 
--------------------------------------------------------------------------------
[2023-03-22T07:27:02.962+0000] {taskinstance.py:1303} INFO - Executing <Task(PythonOperator): load_from_mysql> on 2023-03-22 07:21:59.284653+00:00
[2023-03-22T07:27:02.968+0000] {standard_task_runner.py:55} INFO - Started process 369 to run task
[2023-03-22T07:27:02.972+0000] {standard_task_runner.py:82} INFO - Running: ['***', 'tasks', 'run', 'sql_dags', 'load_from_mysql', 'manual__2023-03-22T07:21:59.284653+00:00', '--job-id', '343', '--raw', '--subdir', 'DAGS_FOLDER/sql_dags.py', '--cfg-path', '/tmp/tmp3urp2kh1']
[2023-03-22T07:27:02.973+0000] {standard_task_runner.py:83} INFO - Job 343: Subtask load_from_mysql
[2023-03-22T07:27:03.221+0000] {task_command.py:388} INFO - Running <TaskInstance: sql_dags.load_from_mysql manual__2023-03-22T07:21:59.284653+00:00 [running]> on host aeff5136c067
[2023-03-22T07:27:03.294+0000] {taskinstance.py:1511} INFO - Exporting the following env vars:
AIRFLOW_CTX_DAG_EMAIL=***@example.com
AIRFLOW_CTX_DAG_OWNER=***
AIRFLOW_CTX_DAG_ID=sql_dags
AIRFLOW_CTX_TASK_ID=load_from_mysql
AIRFLOW_CTX_EXECUTION_DATE=2023-03-22T07:21:59.284653+00:00
AIRFLOW_CTX_TRY_NUMBER=2
AIRFLOW_CTX_DAG_RUN_ID=manual__2023-03-22T07:21:59.284653+00:00
[2023-03-22T07:27:03.297+0000] {logging_mixin.py:137} INFO - 資料庫連接失敗： 2003 (HY000): Can't connect to MySQL server on '127.0.0.1:3306' (111)
[2023-03-22T07:27:03.298+0000] {taskinstance.py:1775} ERROR - Task failed with exception
Traceback (most recent call last):
  File "/home/airflow/.local/lib/python3.7/site-packages/airflow/operators/python.py", line 175, in execute
    return_value = self.execute_callable()
  File "/home/airflow/.local/lib/python3.7/site-packages/airflow/operators/python.py", line 192, in execute_callable
    return self.python_callable(*self.op_args, **self.op_kwargs)
  File "/opt/airflow/dags/sql_dags.py", line 20, in load_mysql
    data = mysql_connector(query, ip, db, user, password)
  File "/opt/airflow/dags/utils/sql.py", line 37, in mysql_connector
    if (connection.is_connected()):
UnboundLocalError: local variable 'connection' referenced before assignment
[2023-03-22T07:27:03.308+0000] {taskinstance.py:1326} INFO - Marking task as FAILED. dag_id=sql_dags, task_id=load_from_mysql, execution_date=20230322T072159, start_date=20230322T072702, end_date=20230322T072703
[2023-03-22T07:27:03.319+0000] {standard_task_runner.py:105} ERROR - Failed to execute job 343 for task load_from_mysql (local variable 'connection' referenced before assignment; 369)
[2023-03-22T07:27:03.346+0000] {local_task_job.py:212} INFO - Task exited with return code 1
[2023-03-22T07:27:03.547+0000] {taskinstance.py:2585} INFO - 0 downstream tasks scheduled from follow-on schedule check
