[2023-03-22T07:50:16.926+0000] {taskinstance.py:1084} INFO - Dependencies all met for dep_context=non-requeueable deps ti=<TaskInstance: sql_dags.write_to_mysql manual__2023-03-22T07:50:15.378126+00:00 [queued]>
[2023-03-22T07:50:16.936+0000] {taskinstance.py:1084} INFO - Dependencies all met for dep_context=requeueable deps ti=<TaskInstance: sql_dags.write_to_mysql manual__2023-03-22T07:50:15.378126+00:00 [queued]>
[2023-03-22T07:50:16.937+0000] {taskinstance.py:1282} INFO - 
--------------------------------------------------------------------------------
[2023-03-22T07:50:16.938+0000] {taskinstance.py:1283} INFO - Starting attempt 1 of 2
[2023-03-22T07:50:16.938+0000] {taskinstance.py:1284} INFO - 
--------------------------------------------------------------------------------
[2023-03-22T07:50:16.955+0000] {taskinstance.py:1303} INFO - Executing <Task(PythonOperator): write_to_mysql> on 2023-03-22 07:50:15.378126+00:00
[2023-03-22T07:50:16.962+0000] {standard_task_runner.py:55} INFO - Started process 1155 to run task
[2023-03-22T07:50:16.967+0000] {standard_task_runner.py:82} INFO - Running: ['***', 'tasks', 'run', 'sql_dags', 'write_to_mysql', 'manual__2023-03-22T07:50:15.378126+00:00', '--job-id', '404', '--raw', '--subdir', 'DAGS_FOLDER/sql_dags.py', '--cfg-path', '/tmp/tmpweys7or0']
[2023-03-22T07:50:16.968+0000] {standard_task_runner.py:83} INFO - Job 404: Subtask write_to_mysql
[2023-03-22T07:50:17.232+0000] {task_command.py:388} INFO - Running <TaskInstance: sql_dags.write_to_mysql manual__2023-03-22T07:50:15.378126+00:00 [running]> on host aeff5136c067
[2023-03-22T07:50:17.317+0000] {taskinstance.py:1511} INFO - Exporting the following env vars:
AIRFLOW_CTX_DAG_EMAIL=***@example.com
AIRFLOW_CTX_DAG_OWNER=***
AIRFLOW_CTX_DAG_ID=sql_dags
AIRFLOW_CTX_TASK_ID=write_to_mysql
AIRFLOW_CTX_EXECUTION_DATE=2023-03-22T07:50:15.378126+00:00
AIRFLOW_CTX_TRY_NUMBER=1
AIRFLOW_CTX_DAG_RUN_ID=manual__2023-03-22T07:50:15.378126+00:00
[2023-03-22T07:50:18.083+0000] {taskinstance.py:1775} ERROR - Task failed with exception
Traceback (most recent call last):
  File "/home/airflow/.local/lib/python3.7/site-packages/airflow/operators/python.py", line 175, in execute
    return_value = self.execute_callable()
  File "/home/airflow/.local/lib/python3.7/site-packages/airflow/operators/python.py", line 192, in execute_callable
    return self.python_callable(*self.op_args, **self.op_kwargs)
  File "/opt/airflow/dags/sql_dags.py", line 33, in write_sotck_to_mysql
    write_batch_insert(df=hist, ip="host.docker.internal", user="chris", password="chris", table="stocks", db="mydatabase")
  File "/opt/airflow/dags/utils/sql.py", line 113, in write_batch_insert
    batch_insert(rec, conn, table, n_col)
  File "/opt/airflow/dags/utils/sql.py", line 103, in batch_insert
    cur.executemany(query, records)
  File "/home/airflow/.local/lib/python3.7/site-packages/pymysql/cursors.py", line 179, in executemany
    self._get_db().encoding,
  File "/home/airflow/.local/lib/python3.7/site-packages/pymysql/cursors.py", line 211, in _do_execute_many
    rows += self.execute(sql + postfix)
  File "/home/airflow/.local/lib/python3.7/site-packages/pymysql/cursors.py", line 148, in execute
    result = self._query(query)
  File "/home/airflow/.local/lib/python3.7/site-packages/pymysql/cursors.py", line 310, in _query
    conn.query(q)
  File "/home/airflow/.local/lib/python3.7/site-packages/pymysql/connections.py", line 548, in query
    self._affected_rows = self._read_query_result(unbuffered=unbuffered)
  File "/home/airflow/.local/lib/python3.7/site-packages/pymysql/connections.py", line 775, in _read_query_result
    result.read()
  File "/home/airflow/.local/lib/python3.7/site-packages/pymysql/connections.py", line 1156, in read
    first_packet = self.connection._read_packet()
  File "/home/airflow/.local/lib/python3.7/site-packages/pymysql/connections.py", line 725, in _read_packet
    packet.raise_for_error()
  File "/home/airflow/.local/lib/python3.7/site-packages/pymysql/protocol.py", line 221, in raise_for_error
    err.raise_mysql_exception(self._data)
  File "/home/airflow/.local/lib/python3.7/site-packages/pymysql/err.py", line 143, in raise_mysql_exception
    raise errorclass(errno, errval)
pymysql.err.OperationalError: (1136, "Column count doesn't match value count at row 1")
[2023-03-22T07:50:18.100+0000] {taskinstance.py:1326} INFO - Marking task as UP_FOR_RETRY. dag_id=sql_dags, task_id=write_to_mysql, execution_date=20230322T075015, start_date=20230322T075016, end_date=20230322T075018
[2023-03-22T07:50:18.113+0000] {standard_task_runner.py:105} ERROR - Failed to execute job 404 for task write_to_mysql ((1136, "Column count doesn't match value count at row 1"); 1155)
[2023-03-22T07:50:18.149+0000] {local_task_job.py:212} INFO - Task exited with return code 1
[2023-03-22T07:50:18.336+0000] {taskinstance.py:2585} INFO - 0 downstream tasks scheduled from follow-on schedule check
